2022-03-19 01:47:49.515728 >>> {command: get_health}
2022-03-19 01:47:49.583029 <<< {isError: false, response: {status: ok}, type: _extensionType, method: ext.flutter.driver}
2022-03-19 01:47:49.624440 >>> {command: request_data, timeout: 1200000}
2022-03-19 01:47:49.679612 <<< {isError: false, response: {message: {"result":"false","failureDetails":["{\"methodName\":\"Test the end to end bloc_login example\",\"details\":\"══╡ EXCEPTION CAUGHT BY FLUTTER TEST FRAMEWORK ╞═════════════════\\nThe following TestFailure was thrown running a test:\\nExpected: exactly one matching node in the widget tree\\n  Actual: _WidgetPredicateFinder:<zero widgets with widget\\nmatching predicate (Closure: (Widget) => bool) (ignoring offstage\\nwidgets)>\\n   Which: means none were found but one was expected\\n\\nWhen the exception was thrown, this was the stack:\\n#4      main.<anonymous closure> (file:///home/kajo/AndroidStudioProjects/bloc_login/test/integration_test/main_test.dart:12:5)\\n#5      main.<anonymous closure> (file:///home/kajo/AndroidStudioProjects/bloc_login/test/integration_test/main_test.dart:8:57)\\n#6      testWidgets.<anonymous closure>.<anonymous closure> (package:flutter_test/src/widget_tester.dart:170:29)\\n<asynchronous suspension>\\n#7      TestWidgetsFlutterBinding._runTestBody (package:flutter_test/src/binding.dart:833:5)\\n<asynchronous suspension>\\n\\nThis was caught by the test expectation on the following line:\\n  file:///home/kajo/AndroidStudioProjects/bloc_login/test/integration_test/main_test.dart line 12\\nThe test description was:\\n  Test the end to end bloc_login example\\n═════════════════════════════════════════════════════════════════\\n\"}"]}}, type: _extensionType, method: ext.flutter.driver}
2022-03-19 01:59:29.437200 >>> {command: get_health}
2022-03-19 01:59:29.559341 <<< {isError: false, response: {status: ok}, type: _extensionType, method: ext.flutter.driver}
2022-03-19 01:59:29.598583 >>> {command: request_data, timeout: 1200000}
2022-03-19 01:59:29.654057 <<< {isError: false, response: {message: {"result":"false","failureDetails":["{\"methodName\":\"Test the end to end bloc_login example\",\"details\":\"══╡ EXCEPTION CAUGHT BY FLUTTER TEST FRAMEWORK ╞═════════════════\\nThe following TestFailure was thrown running a test:\\nExpected: exactly one matching node in the widget tree\\n  Actual: _TextFinder:<zero widgets with text \\\"Login\\\" (ignoring\\noffstage widgets)>\\n   Which: means none were found but one was expected\\n\\nWhen the exception was thrown, this was the stack:\\n#4      main.<anonymous closure> (file:///home/kajo/AndroidStudioProjects/bloc_login/test/integration_test/main_test.dart:16:5)\\n#5      main.<anonymous closure> (file:///home/kajo/AndroidStudioProjects/bloc_login/test/integration_test/main_test.dart:8:57)\\n#6      testWidgets.<anonymous closure>.<anonymous closure> (package:flutter_test/src/widget_tester.dart:170:29)\\n<asynchronous suspension>\\n#7      TestWidgetsFlutterBinding._runTestBody (package:flutter_test/src/binding.dart:833:5)\\n<asynchronous suspension>\\n\\nThis was caught by the test expectation on the following line:\\n  file:///home/kajo/AndroidStudioProjects/bloc_login/test/integration_test/main_test.dart line 16\\nThe test description was:\\n  Test the end to end bloc_login example\\n═════════════════════════════════════════════════════════════════\\n\"}"]}}, type: _extensionType, method: ext.flutter.driver}
2022-03-19 02:09:55.004634 >>> {command: get_health}
2022-03-19 02:09:55.455230 <<< {isError: false, response: {status: ok}, type: _extensionType, method: ext.flutter.driver}
2022-03-19 02:09:55.491250 >>> {command: request_data, timeout: 1200000}
2022-03-19 02:09:56.623515 <<< {isError: false, response: {message: {"result":"false","failureDetails":["{\"methodName\":\"Test the end to end bloc_login example\",\"details\":\"══╡ EXCEPTION CAUGHT BY FLUTTER TEST FRAMEWORK ╞═════════════════\\nThe following TestFailure was thrown running a test:\\nExpected: exactly one matching node in the widget tree\\n  Actual: _WidgetPredicateFinder:<zero widgets with widget\\nmatching predicate (Closure: (Widget) => bool) (ignoring offstage\\nwidgets)>\\n   Which: means none were found but one was expected\\n\\nWhen the exception was thrown, this was the stack:\\n#4      main.<anonymous closure> (file:///home/kajo/AndroidStudioProjects/bloc_login/test/integration_test/main_test.dart:13:5)\\n#5      main.<anonymous closure> (file:///home/kajo/AndroidStudioProjects/bloc_login/test/integration_test/main_test.dart:9:57)\\n#6      testWidgets.<anonymous closure>.<anonymous closure> (package:flutter_test/src/widget_tester.dart:170:29)\\n<asynchronous suspension>\\n#7      TestWidgetsFlutterBinding._runTestBody (package:flutter_test/src/binding.dart:833:5)\\n<asynchronous suspension>\\n\\nThis was caught by the test expectation on the following line:\\n  file:///home/kajo/AndroidStudioProjects/bloc_login/test/integration_test/main_test.dart line 13\\nThe test description was:\\n  Test the end to end bloc_login example\\n═════════════════════════════════════════════════════════════════\\n\"}"]}}, type: _extensionType, method: ext.flutter.driver}
2022-03-19 02:13:45.327115 >>> {command: get_health}
2022-03-19 02:13:45.594262 <<< {isError: false, response: {status: ok}, type: _extensionType, method: ext.flutter.driver}
2022-03-19 02:13:45.624978 >>> {command: request_data, timeout: 1200000}
2022-03-19 02:13:48.986690 <<< {isError: false, response: {message: {"result":"false","failureDetails":["{\"methodName\":\"Test the end to end bloc_login example\",\"details\":\"══╡ EXCEPTION CAUGHT BY FLUTTER TEST FRAMEWORK ╞═════════════════\\nThe following TestFailure was thrown running a test:\\nExpected: exactly one matching node in the widget tree\\n  Actual: _WidgetPredicateFinder:<zero widgets with widget\\nmatching predicate (Closure: (Widget) => bool) (ignoring offstage\\nwidgets)>\\n   Which: means none were found but one was expected\\n\\nWhen the exception was thrown, this was the stack:\\n#4      main.<anonymous closure> (file:///home/kajo/AndroidStudioProjects/bloc_login/test/integration_test/main_test.dart:14:5)\\n<asynchronous suspension>\\n#5      testWidgets.<anonymous closure>.<anonymous closure> (package:flutter_test/src/widget_tester.dart:170:15)\\n<asynchronous suspension>\\n#6      TestWidgetsFlutterBinding._runTestBody (package:flutter_test/src/binding.dart:833:5)\\n<asynchronous suspension>\\n\\nThis was caught by the test expectation on the following line:\\n  file:///home/kajo/AndroidStudioProjects/bloc_login/test/integration_test/main_test.dart line 14\\nThe test description was:\\n  Test the end to end bloc_login example\\n═════════════════════════════════════════════════════════════════\\n\"}"]}}, type: _extensionType, method: ext.flutter.driver}
2022-03-19 02:16:00.801471 >>> {command: get_health}
2022-03-19 02:16:01.094987 <<< {isError: false, response: {status: ok}, type: _extensionType, method: ext.flutter.driver}
2022-03-19 02:16:01.130818 >>> {command: request_data, timeout: 1200000}
2022-03-19 02:16:04.501816 <<< {isError: false, response: {message: {"result":"false","failureDetails":["{\"methodName\":\"Test the end to end bloc_login example\",\"details\":\"══╡ EXCEPTION CAUGHT BY FLUTTER TEST FRAMEWORK ╞═════════════════\\nThe following TestFailure was thrown running a test:\\nExpected: exactly 2 matching nodes in the widget tree\\n  Actual: _TextFinder:<zero widgets with text \\\"Login\\\">\\n   Which: means none were found but some were expected\\n\\nWhen the exception was thrown, this was the stack:\\n#4      main.<anonymous closure> (file:///home/kajo/AndroidStudioProjects/bloc_login/test/integration_test/main_test.dart:18:5)\\n<asynchronous suspension>\\n#5      testWidgets.<anonymous closure>.<anonymous closure> (package:flutter_test/src/widget_tester.dart:170:15)\\n<asynchronous suspension>\\n#6      TestWidgetsFlutterBinding._runTestBody (package:flutter_test/src/binding.dart:833:5)\\n<asynchronous suspension>\\n\\nThis was caught by the test expectation on the following line:\\n  file:///home/kajo/AndroidStudioProjects/bloc_login/test/integration_test/main_test.dart line 18\\nThe test description was:\\n  Test the end to end bloc_login example\\n═════════════════════════════════════════════════════════════════\\n\"}"]}}, type: _extensionType, method: ext.flutter.driver}
2022-03-19 02:27:13.122701 >>> {command: get_health}
2022-03-19 02:27:13.407624 <<< {isError: false, response: {status: ok}, type: _extensionType, method: ext.flutter.driver}
2022-03-19 02:27:13.451346 >>> {command: request_data, timeout: 1200000}
2022-03-19 02:27:16.758463 <<< {isError: false, response: {message: {"result":"false","failureDetails":["{\"methodName\":\"Test the end to end bloc_login example\",\"details\":\"══╡ EXCEPTION CAUGHT BY FLUTTER TEST FRAMEWORK ╞═════════════════\\nThe following TestFailure was thrown running a test:\\nExpected: exactly one matching node in the widget tree\\n  Actual: _WidgetPredicateFinder:<zero widgets with widget\\nmatching predicate (Closure: (Widget) => bool) (ignoring offstage\\nwidgets)>\\n   Which: means none were found but one was expected\\n\\nWhen the exception was thrown, this was the stack:\\n#4      main.<anonymous closure> (file:///home/kajo/AndroidStudioProjects/bloc_login/test/integration_test/main_test.dart:14:5)\\n<asynchronous suspension>\\n#5      testWidgets.<anonymous closure>.<anonymous closure> (package:flutter_test/src/widget_tester.dart:170:15)\\n<asynchronous suspension>\\n#6      TestWidgetsFlutterBinding._runTestBody (package:flutter_test/src/binding.dart:833:5)\\n<asynchronous suspension>\\n\\nThis was caught by the test expectation on the following line:\\n  file:///home/kajo/AndroidStudioProjects/bloc_login/test/integration_test/main_test.dart line 14\\nThe test description was:\\n  Test the end to end bloc_login example\\n═════════════════════════════════════════════════════════════════\\n\"}"]}}, type: _extensionType, method: ext.flutter.driver}
2022-03-19 02:31:56.583338 >>> {command: get_health}
2022-03-19 02:31:56.763380 <<< {isError: false, response: {status: ok}, type: _extensionType, method: ext.flutter.driver}
2022-03-19 02:31:56.812351 >>> {command: request_data, timeout: 1200000}
2022-03-19 02:31:59.822193 <<< {isError: false, response: {message: {"result":"false","failureDetails":["{\"methodName\":\"Test the end to end bloc_login example\",\"details\":\"══╡ EXCEPTION CAUGHT BY FLUTTER TEST FRAMEWORK ╞═════════════════\\nThe following TestFailure was thrown running a test:\\nExpected: exactly one matching node in the widget tree\\n  Actual: _WidgetPredicateFinder:<zero widgets with widget\\nmatching predicate (Closure: (Widget) => bool) (ignoring offstage\\nwidgets)>\\n   Which: means none were found but one was expected\\n\\nWhen the exception was thrown, this was the stack:\\n#4      main.<anonymous closure> (file:///home/kajo/AndroidStudioProjects/bloc_login/test/integration_test/main_test.dart:15:5)\\n<asynchronous suspension>\\n#5      testWidgets.<anonymous closure>.<anonymous closure> (package:flutter_test/src/widget_tester.dart:170:15)\\n<asynchronous suspension>\\n#6      TestWidgetsFlutterBinding._runTestBody (package:flutter_test/src/binding.dart:833:5)\\n<asynchronous suspension>\\n\\nThis was caught by the test expectation on the following line:\\n  file:///home/kajo/AndroidStudioProjects/bloc_login/test/integration_test/main_test.dart line 15\\nThe test description was:\\n  Test the end to end bloc_login example\\n═════════════════════════════════════════════════════════════════\\n\"}"]}}, type: _extensionType, method: ext.flutter.driver}
2022-03-19 02:37:17.854780 >>> {command: get_health}
2022-03-19 02:37:18.035598 <<< {isError: false, response: {status: ok}, type: _extensionType, method: ext.flutter.driver}
2022-03-19 02:37:18.122377 >>> {command: request_data, timeout: 1200000}
2022-03-19 02:37:23.102001 <<< {isError: false, response: {message: {"result":"false","failureDetails":["{\"methodName\":\"Test the end to end bloc_login example\",\"details\":\"══╡ EXCEPTION CAUGHT BY FLUTTER TEST FRAMEWORK ╞═════════════════\\nThe following TestFailure was thrown running a test:\\nExpected: exactly one matching node in the widget tree\\n  Actual: _WidgetPredicateFinder:<zero widgets with widget\\nmatching predicate (Closure: (Widget) => bool) (ignoring offstage\\nwidgets)>\\n   Which: means none were found but one was expected\\n\\nWhen the exception was thrown, this was the stack:\\n#4      main.<anonymous closure> (file:///home/kajo/AndroidStudioProjects/bloc_login/test/integration_test/main_test.dart:16:5)\\n<asynchronous suspension>\\n#5      testWidgets.<anonymous closure>.<anonymous closure> (package:flutter_test/src/widget_tester.dart:170:15)\\n<asynchronous suspension>\\n#6      TestWidgetsFlutterBinding._runTestBody (package:flutter_test/src/binding.dart:833:5)\\n<asynchronous suspension>\\n\\nThis was caught by the test expectation on the following line:\\n  file:///home/kajo/AndroidStudioProjects/bloc_login/test/integration_test/main_test.dart line 16\\nThe test description was:\\n  Test the end to end bloc_login example\\n═════════════════════════════════════════════════════════════════\\n\"}"]}}, type: _extensionType, method: ext.flutter.driver}
2022-03-19 02:40:02.524213 >>> {command: get_health}
2022-03-19 02:40:02.820027 <<< {isError: false, response: {status: ok}, type: _extensionType, method: ext.flutter.driver}
2022-03-19 02:40:02.851845 >>> {command: request_data, timeout: 1200000}
2022-03-19 02:40:07.804873 <<< {isError: false, response: {message: {"result":"false","failureDetails":["{\"methodName\":\"Test the end to end bloc_login example\",\"details\":\"══╡ EXCEPTION CAUGHT BY FLUTTER TEST FRAMEWORK ╞═════════════════\\nThe following TestFailure was thrown running a test:\\nExpected: exactly one matching node in the widget tree\\n  Actual: _WidgetPredicateFinder:<zero widgets with widget\\nmatching predicate (Closure: (Widget) => bool) (ignoring offstage\\nwidgets)>\\n   Which: means none were found but one was expected\\n\\nWhen the exception was thrown, this was the stack:\\n#4      main.<anonymous closure> (file:///home/kajo/AndroidStudioProjects/bloc_login/test/integration_test/main_test.dart:16:5)\\n<asynchronous suspension>\\n#5      testWidgets.<anonymous closure>.<anonymous closure> (package:flutter_test/src/widget_tester.dart:170:15)\\n<asynchronous suspension>\\n#6      TestWidgetsFlutterBinding._runTestBody (package:flutter_test/src/binding.dart:833:5)\\n<asynchronous suspension>\\n\\nThis was caught by the test expectation on the following line:\\n  file:///home/kajo/AndroidStudioProjects/bloc_login/test/integration_test/main_test.dart line 16\\nThe test description was:\\n  Test the end to end bloc_login example\\n═════════════════════════════════════════════════════════════════\\n\"}"]}}, type: _extensionType, method: ext.flutter.driver}
2022-03-19 02:44:43.133885 >>> {command: get_health}
2022-03-19 02:44:43.315410 <<< {isError: false, response: {status: ok}, type: _extensionType, method: ext.flutter.driver}
2022-03-19 02:44:43.360990 >>> {command: request_data, timeout: 1200000}
2022-03-19 02:44:50.739650 <<< {isError: false, response: {message: {"result":"false","failureDetails":["{\"methodName\":\"Test the end to end bloc_login example\",\"details\":\"══╡ EXCEPTION CAUGHT BY FLUTTER TEST FRAMEWORK ╞═════════════════\\nThe following message was thrown:\\nMultiple exceptions (2) were detected during the running of the\\ncurrent test, and at least one was unexpected.\\n═════════════════════════════════════════════════════════════════\\n\"}"]}}, type: _extensionType, method: ext.flutter.driver}
2022-03-19 02:46:41.400740 >>> {command: get_health}
2022-03-19 02:46:41.588569 <<< {isError: false, response: {status: ok}, type: _extensionType, method: ext.flutter.driver}
2022-03-19 02:46:41.621327 >>> {command: request_data, timeout: 1200000}
2022-03-19 02:46:48.922726 <<< {isError: false, response: {message: {"result":"false","failureDetails":["{\"methodName\":\"Test the end to end bloc_login example\",\"details\":\"══╡ EXCEPTION CAUGHT BY FLUTTER TEST FRAMEWORK ╞═════════════════\\nThe following message was thrown:\\nMultiple exceptions (2) were detected during the running of the\\ncurrent test, and at least one was unexpected.\\n═════════════════════════════════════════════════════════════════\\n\"}"]}}, type: _extensionType, method: ext.flutter.driver}
2022-03-19 02:49:21.470989 >>> {command: get_health}
2022-03-19 02:49:21.771951 <<< {isError: false, response: {status: ok}, type: _extensionType, method: ext.flutter.driver}
2022-03-19 02:49:21.812090 >>> {command: request_data, timeout: 1200000}
2022-03-19 02:49:29.243445 <<< {isError: false, response: {message: {"result":"false","failureDetails":["{\"methodName\":\"Test the end to end bloc_login example\",\"details\":\"══╡ EXCEPTION CAUGHT BY FLUTTER TEST FRAMEWORK ╞═════════════════\\nThe following message was thrown:\\nMultiple exceptions (2) were detected during the running of the\\ncurrent test, and at least one was unexpected.\\n═════════════════════════════════════════════════════════════════\\n\"}"]}}, type: _extensionType, method: ext.flutter.driver}
2022-03-19 02:53:09.933868 >>> {command: get_health}
2022-03-19 02:53:10.142975 <<< {isError: false, response: {status: ok}, type: _extensionType, method: ext.flutter.driver}
2022-03-19 02:53:10.179975 >>> {command: request_data, timeout: 1200000}
2022-03-19 02:53:17.429628 <<< {isError: false, response: {message: {"result":"false","failureDetails":["{\"methodName\":\"Test the end to end bloc_login example\",\"details\":\"══╡ EXCEPTION CAUGHT BY FLUTTER TEST FRAMEWORK ╞═════════════════\\nThe following message was thrown:\\nMultiple exceptions (2) were detected during the running of the\\ncurrent test, and at least one was unexpected.\\n═════════════════════════════════════════════════════════════════\\n\"}"]}}, type: _extensionType, method: ext.flutter.driver}
2022-03-19 02:57:54.517128 >>> {command: get_health}
2022-03-19 02:57:54.701195 <<< {isError: false, response: {status: ok}, type: _extensionType, method: ext.flutter.driver}
2022-03-19 02:57:54.737929 >>> {command: request_data, timeout: 1200000}
2022-03-19 02:58:01.998792 <<< {isError: false, response: {message: {"result":"false","failureDetails":["{\"methodName\":\"Test the end to end bloc_login example\",\"details\":\"══╡ EXCEPTION CAUGHT BY FLUTTER TEST FRAMEWORK ╞═════════════════\\nThe following message was thrown:\\nMultiple exceptions (2) were detected during the running of the\\ncurrent test, and at least one was unexpected.\\n═════════════════════════════════════════════════════════════════\\n\"}"]}}, type: _extensionType, method: ext.flutter.driver}
2022-03-19 03:03:24.838165 >>> {command: get_health}
2022-03-19 03:03:25.011487 <<< {isError: false, response: {status: ok}, type: _extensionType, method: ext.flutter.driver}
2022-03-19 03:03:25.051240 >>> {command: request_data, timeout: 1200000}
2022-03-19 03:03:32.350329 <<< {isError: false, response: {message: {"result":"false","failureDetails":["{\"methodName\":\"Test the end to end bloc_login example\",\"details\":\"══╡ EXCEPTION CAUGHT BY FLUTTER TEST FRAMEWORK ╞═════════════════\\nThe following message was thrown:\\nMultiple exceptions (2) were detected during the running of the\\ncurrent test, and at least one was unexpected.\\n═════════════════════════════════════════════════════════════════\\n\"}"]}}, type: _extensionType, method: ext.flutter.driver}
2022-03-19 03:06:46.791373 >>> {command: get_health}
2022-03-19 03:06:46.977833 <<< {isError: false, response: {status: ok}, type: _extensionType, method: ext.flutter.driver}
2022-03-19 03:06:47.019092 >>> {command: request_data, timeout: 1200000}
2022-03-19 03:06:47.928416 <<< {isError: false, response: {message: {"result":"false","failureDetails":["{\"methodName\":\"Test the end to end bloc_login example\",\"details\":\"══╡ EXCEPTION CAUGHT BY FLUTTER TEST FRAMEWORK ╞═════════════════\\nThe following TestFailure was thrown running a test:\\nExpected: exactly one matching node in the widget tree\\n  Actual: _WidgetPredicateFinder:<zero widgets with widget\\nmatching predicate (Closure: (Widget) => bool) (ignoring offstage\\nwidgets)>\\n   Which: means none were found but one was expected\\n\\nWhen the exception was thrown, this was the stack:\\n#4      main.<anonymous closure> (file:///home/kajo/AndroidStudioProjects/bloc_login/test/integration_test/main_test.dart:22:5)\\n#5      main.<anonymous closure> (file:///home/kajo/AndroidStudioProjects/bloc_login/test/integration_test/main_test.dart:13:57)\\n#6      testWidgets.<anonymous closure>.<anonymous closure> (package:flutter_test/src/widget_tester.dart:170:29)\\n<asynchronous suspension>\\n#7      TestWidgetsFlutterBinding._runTestBody (package:flutter_test/src/binding.dart:833:5)\\n<asynchronous suspension>\\n\\nThis was caught by the test expectation on the following line:\\n  file:///home/kajo/AndroidStudioProjects/bloc_login/test/integration_test/main_test.dart line 22\\nThe test description was:\\n  Test the end to end bloc_login example\\n═════════════════════════════════════════════════════════════════\\n\"}"]}}, type: _extensionType, method: ext.flutter.driver}
2022-03-19 03:08:29.762139 >>> {command: get_health}
2022-03-19 03:08:30.053548 <<< {isError: false, response: {status: ok}, type: _extensionType, method: ext.flutter.driver}
2022-03-19 03:08:30.169720 >>> {command: request_data, timeout: 1200000}
2022-03-19 03:09:03.211344 <<< {isError: false, response: {message: {"result":"false","failureDetails":["{\"methodName\":\"Test the end to end bloc_login example\",\"details\":\"══╡ EXCEPTION CAUGHT BY FLUTTER TEST FRAMEWORK ╞═════════════════\\nThe following message was thrown:\\nMultiple exceptions (2) were detected during the running of the\\ncurrent test, and at least one was unexpected.\\n═════════════════════════════════════════════════════════════════\\n\"}"]}}, type: _extensionType, method: ext.flutter.driver}
2022-03-19 12:24:57.096141 >>> {command: get_health}
2022-03-19 12:24:57.409436 <<< {isError: false, response: {status: ok}, type: _extensionType, method: ext.flutter.driver}
2022-03-19 12:24:57.480829 >>> {command: request_data, timeout: 1200000}
2022-03-19 12:24:57.601265 <<< {isError: false, response: {message: {"result":"true","failureDetails":[]}}, type: _extensionType, method: ext.flutter.driver}
2022-03-19 12:34:04.843942 >>> {command: get_health}
2022-03-19 12:34:05.016213 <<< {isError: false, response: {status: ok}, type: _extensionType, method: ext.flutter.driver}
2022-03-19 12:34:05.050881 >>> {command: request_data, timeout: 1200000}
2022-03-19 12:34:06.101887 <<< {isError: false, response: {message: {"result":"false","failureDetails":["{\"methodName\":\"tap on the floating action button, verify counter\",\"details\":\"══╡ EXCEPTION CAUGHT BY FLUTTER TEST FRAMEWORK ╞═════════════════\\nThe following TestFailure was thrown running a test:\\nExpected: exactly one matching node in the widget tree\\n  Actual: _TextFinder:<zero widgets with text \\\"Login\\\" (ignoring\\noffstage widgets)>\\n   Which: means none were found but one was expected\\n\\nWhen the exception was thrown, this was the stack:\\n#4      main.<anonymous closure>.<anonymous closure> (file:///home/kajo/AndroidStudioProjects/bloc_login/test/integration_test/main_test.dart:52:11)\\n<asynchronous suspension>\\n#5      testWidgets.<anonymous closure>.<anonymous closure> (package:flutter_test/src/widget_tester.dart:170:15)\\n<asynchronous suspension>\\n#6      TestWidgetsFlutterBinding._runTestBody (package:flutter_test/src/binding.dart:833:5)\\n<asynchronous suspension>\\n\\nThis was caught by the test expectation on the following line:\\n  file:///home/kajo/AndroidStudioProjects/bloc_login/test/integration_test/main_test.dart line 52\\nThe test description was:\\n  tap on the floating action button, verify counter\\n═════════════════════════════════════════════════════════════════\\n\"}"]}}, type: _extensionType, method: ext.flutter.driver}
2022-03-19 12:44:51.210782 >>> {command: get_health}
2022-03-19 12:44:51.372740 <<< {isError: false, response: {status: ok}, type: _extensionType, method: ext.flutter.driver}
2022-03-19 12:44:51.402576 >>> {command: request_data, timeout: 1200000}
2022-03-19 12:44:52.496595 <<< {isError: false, response: {message: {"result":"false","failureDetails":["{\"methodName\":\"show error msg \",\"details\":\"══╡ EXCEPTION CAUGHT BY FLUTTER TEST FRAMEWORK ╞═════════════════\\nThe following TestFailure was thrown running a test:\\nExpected: exactly one matching node in the widget tree\\n  Actual: _TextFinder:<zero widgets with text \\\"LoginTXT\\\"\\n(ignoring offstage widgets)>\\n   Which: means none were found but one was expected\\n\\nWhen the exception was thrown, this was the stack:\\n#4      main.<anonymous closure>.<anonymous closure> (file:///home/kajo/AndroidStudioProjects/bloc_login/test/integration_test/main_test.dart:52:11)\\n<asynchronous suspension>\\n#5      testWidgets.<anonymous closure>.<anonymous closure> (package:flutter_test/src/widget_tester.dart:170:15)\\n<asynchronous suspension>\\n#6      TestWidgetsFlutterBinding._runTestBody (package:flutter_test/src/binding.dart:833:5)\\n<asynchronous suspension>\\n\\nThis was caught by the test expectation on the following line:\\n  file:///home/kajo/AndroidStudioProjects/bloc_login/test/integration_test/main_test.dart line 52\\nThe test description was:\\n  show error msg\\n═════════════════════════════════════════════════════════════════\\n\"}"]}}, type: _extensionType, method: ext.flutter.driver}
2022-03-19 13:13:17.209217 >>> {command: get_health}
2022-03-19 13:13:17.437366 <<< {isError: false, response: {status: ok}, type: _extensionType, method: ext.flutter.driver}
2022-03-19 13:13:17.473679 >>> {command: request_data, timeout: 1200000}
2022-03-19 13:13:18.896486 <<< {isError: false, response: {message: {"result":"false","failureDetails":["{\"methodName\":\"Can Login \",\"details\":\"══╡ EXCEPTION CAUGHT BY FLUTTER TEST FRAMEWORK ╞═════════════════\\nThe following TestFailure was thrown running a test:\\nExpected: exactly one matching node in the widget tree\\n  Actual: _WidgetPredicateFinder:<zero widgets with widget\\nmatching predicate (Closure: (Widget) => bool) (ignoring offstage\\nwidgets)>\\n   Which: means none were found but one was expected\\n\\nWhen the exception was thrown, this was the stack:\\n#4      main.<anonymous closure> (file:///home/kajo/AndroidStudioProjects/bloc_login/test/integration_test/main_test.dart:19:5)\\n<asynchronous suspension>\\n#5      testWidgets.<anonymous closure>.<anonymous closure> (package:flutter_test/src/widget_tester.dart:170:15)\\n<asynchronous suspension>\\n#6      TestWidgetsFlutterBinding._runTestBody (package:flutter_test/src/binding.dart:833:5)\\n<asynchronous suspension>\\n\\nThis was caught by the test expectation on the following line:\\n  file:///home/kajo/AndroidStudioProjects/bloc_login/test/integration_test/main_test.dart line 19\\nThe test description was:\\n  Can Login\\n═════════════════════════════════════════════════════════════════\\n\"}"]}}, type: _extensionType, method: ext.flutter.driver}
2022-03-19 13:16:31.224620 >>> {command: get_health}
2022-03-19 13:16:31.429518 <<< {isError: false, response: {status: ok}, type: _extensionType, method: ext.flutter.driver}
2022-03-19 13:16:31.465925 >>> {command: request_data, timeout: 1200000}
2022-03-19 13:16:32.560414 <<< {isError: false, response: {message: {"result":"false","failureDetails":["{\"methodName\":\"Can Login \",\"details\":\"══╡ EXCEPTION CAUGHT BY FLUTTER TEST FRAMEWORK ╞═════════════════\\nThe following TestFailure was thrown running a test:\\nExpected: exactly one matching node in the widget tree\\n  Actual: _WidgetPredicateFinder:<zero widgets with widget\\nmatching predicate (Closure: (Widget) => bool) (ignoring offstage\\nwidgets)>\\n   Which: means none were found but one was expected\\n\\nWhen the exception was thrown, this was the stack:\\n#4      main.<anonymous closure> (file:///home/kajo/AndroidStudioProjects/bloc_login/test/integration_test/main_test.dart:19:5)\\n<asynchronous suspension>\\n#5      testWidgets.<anonymous closure>.<anonymous closure> (package:flutter_test/src/widget_tester.dart:170:15)\\n<asynchronous suspension>\\n#6      TestWidgetsFlutterBinding._runTestBody (package:flutter_test/src/binding.dart:833:5)\\n<asynchronous suspension>\\n\\nThis was caught by the test expectation on the following line:\\n  file:///home/kajo/AndroidStudioProjects/bloc_login/test/integration_test/main_test.dart line 19\\nThe test description was:\\n  Can Login\\n═════════════════════════════════════════════════════════════════\\n\"}"]}}, type: _extensionType, method: ext.flutter.driver}
2022-03-19 13:17:29.974773 >>> {command: get_health}
2022-03-19 13:17:30.157211 <<< {isError: false, response: {status: ok}, type: _extensionType, method: ext.flutter.driver}
2022-03-19 13:17:30.195193 >>> {command: request_data, timeout: 1200000}
2022-03-19 13:17:31.268651 <<< {isError: false, response: {message: {"result":"false","failureDetails":["{\"methodName\":\"Can Login \",\"details\":\"══╡ EXCEPTION CAUGHT BY FLUTTER TEST FRAMEWORK ╞═════════════════\\nThe following TestFailure was thrown running a test:\\nExpected: exactly one matching node in the widget tree\\n  Actual: _WidgetPredicateFinder:<zero widgets with widget\\nmatching predicate (Closure: (Widget) => bool) (ignoring offstage\\nwidgets)>\\n   Which: means none were found but one was expected\\n\\nWhen the exception was thrown, this was the stack:\\n#4      main.<anonymous closure> (file:///home/kajo/AndroidStudioProjects/bloc_login/test/integration_test/main_test.dart:19:5)\\n<asynchronous suspension>\\n#5      testWidgets.<anonymous closure>.<anonymous closure> (package:flutter_test/src/widget_tester.dart:170:15)\\n<asynchronous suspension>\\n#6      TestWidgetsFlutterBinding._runTestBody (package:flutter_test/src/binding.dart:833:5)\\n<asynchronous suspension>\\n\\nThis was caught by the test expectation on the following line:\\n  file:///home/kajo/AndroidStudioProjects/bloc_login/test/integration_test/main_test.dart line 19\\nThe test description was:\\n  Can Login\\n═════════════════════════════════════════════════════════════════\\n\"}"]}}, type: _extensionType, method: ext.flutter.driver}
2022-03-19 13:18:22.513786 >>> {command: get_health}
2022-03-19 13:18:22.692158 <<< {isError: false, response: {status: ok}, type: _extensionType, method: ext.flutter.driver}
2022-03-19 13:18:22.732612 >>> {command: request_data, timeout: 1200000}
2022-03-19 13:18:23.794850 <<< {isError: false, response: {message: {"result":"false","failureDetails":["{\"methodName\":\"Can Login \",\"details\":\"══╡ EXCEPTION CAUGHT BY FLUTTER TEST FRAMEWORK ╞═════════════════\\nThe following TestFailure was thrown running a test:\\nExpected: exactly one matching node in the widget tree\\n  Actual: _WidgetPredicateFinder:<zero widgets with widget\\nmatching predicate (Closure: (Widget) => bool) (ignoring offstage\\nwidgets)>\\n   Which: means none were found but one was expected\\n\\nWhen the exception was thrown, this was the stack:\\n#4      main.<anonymous closure> (file:///home/kajo/AndroidStudioProjects/bloc_login/test/integration_test/main_test.dart:19:5)\\n<asynchronous suspension>\\n#5      testWidgets.<anonymous closure>.<anonymous closure> (package:flutter_test/src/widget_tester.dart:170:15)\\n<asynchronous suspension>\\n#6      TestWidgetsFlutterBinding._runTestBody (package:flutter_test/src/binding.dart:833:5)\\n<asynchronous suspension>\\n\\nThis was caught by the test expectation on the following line:\\n  file:///home/kajo/AndroidStudioProjects/bloc_login/test/integration_test/main_test.dart line 19\\nThe test description was:\\n  Can Login\\n═════════════════════════════════════════════════════════════════\\n\"}"]}}, type: _extensionType, method: ext.flutter.driver}
2022-03-19 13:19:54.667382 >>> {command: get_health}
2022-03-19 13:19:54.952994 <<< {isError: false, response: {status: ok}, type: _extensionType, method: ext.flutter.driver}
2022-03-19 13:19:54.991786 >>> {command: request_data, timeout: 1200000}
2022-03-19 13:19:56.045175 <<< {isError: false, response: {message: {"result":"false","failureDetails":["{\"methodName\":\"Can Login \",\"details\":\"══╡ EXCEPTION CAUGHT BY FLUTTER TEST FRAMEWORK ╞═════════════════\\nThe following TestFailure was thrown running a test:\\nExpected: exactly one matching node in the widget tree\\n  Actual: _WidgetPredicateFinder:<zero widgets with widget\\nmatching predicate (Closure: (Widget) => bool)>\\n   Which: means none were found but one was expected\\n\\nWhen the exception was thrown, this was the stack:\\n#4      main.<anonymous closure> (file:///home/kajo/AndroidStudioProjects/bloc_login/test/integration_test/main_test.dart:19:5)\\n<asynchronous suspension>\\n#5      testWidgets.<anonymous closure>.<anonymous closure> (package:flutter_test/src/widget_tester.dart:170:15)\\n<asynchronous suspension>\\n#6      TestWidgetsFlutterBinding._runTestBody (package:flutter_test/src/binding.dart:833:5)\\n<asynchronous suspension>\\n\\nThis was caught by the test expectation on the following line:\\n  file:///home/kajo/AndroidStudioProjects/bloc_login/test/integration_test/main_test.dart line 19\\nThe test description was:\\n  Can Login\\n═════════════════════════════════════════════════════════════════\\n\"}"]}}, type: _extensionType, method: ext.flutter.driver}
2022-03-19 13:28:09.910474 >>> {command: get_health}
2022-03-19 13:28:10.175599 <<< {isError: false, response: {status: ok}, type: _extensionType, method: ext.flutter.driver}
2022-03-19 13:28:10.208331 >>> {command: request_data, timeout: 1200000}
2022-03-19 13:28:11.147815 <<< {isError: false, response: {message: {"result":"false","failureDetails":["{\"methodName\":\"Can Login \",\"details\":\"══╡ EXCEPTION CAUGHT BY FLUTTER TEST FRAMEWORK ╞═════════════════\\nThe following TestFailure was thrown running a test:\\nExpected: exactly one matching node in the widget tree\\n  Actual: _WidgetPredicateFinder:<zero widgets with widget\\nmatching predicate (Closure: (Widget) => bool)>\\n   Which: means none were found but one was expected\\n\\nWhen the exception was thrown, this was the stack:\\n#4      main.<anonymous closure> (file:///home/kajo/AndroidStudioProjects/bloc_login/test/integration_test/main_test.dart:19:5)\\n<asynchronous suspension>\\n#5      testWidgets.<anonymous closure>.<anonymous closure> (package:flutter_test/src/widget_tester.dart:170:15)\\n<asynchronous suspension>\\n#6      TestWidgetsFlutterBinding._runTestBody (package:flutter_test/src/binding.dart:833:5)\\n<asynchronous suspension>\\n\\nThis was caught by the test expectation on the following line:\\n  file:///home/kajo/AndroidStudioProjects/bloc_login/test/integration_test/main_test.dart line 19\\nThe test description was:\\n  Can Login\\n═════════════════════════════════════════════════════════════════\\n\"}"]}}, type: _extensionType, method: ext.flutter.driver}
2022-03-19 13:32:37.118867 >>> {command: get_health}
2022-03-19 13:32:37.406477 <<< {isError: false, response: {status: ok}, type: _extensionType, method: ext.flutter.driver}
2022-03-19 13:32:37.455223 >>> {command: request_data, timeout: 1200000}
2022-03-19 13:32:38.378865 <<< {isError: false, response: {message: {"result":"false","failureDetails":["{\"methodName\":\"Can Login \",\"details\":\"══╡ EXCEPTION CAUGHT BY FLUTTER TEST FRAMEWORK ╞═════════════════\\nThe following TestFailure was thrown running a test:\\nExpected: exactly one matching node in the widget tree\\n  Actual: _WidgetPredicateFinder:<zero widgets with widget\\nmatching predicate (Closure: (Widget) => bool)>\\n   Which: means none were found but one was expected\\n\\nWhen the exception was thrown, this was the stack:\\n#4      main.<anonymous closure> (file:///home/kajo/AndroidStudioProjects/bloc_login/test/integration_test/main_test.dart:19:5)\\n<asynchronous suspension>\\n#5      testWidgets.<anonymous closure>.<anonymous closure> (package:flutter_test/src/widget_tester.dart:170:15)\\n<asynchronous suspension>\\n#6      TestWidgetsFlutterBinding._runTestBody (package:flutter_test/src/binding.dart:833:5)\\n<asynchronous suspension>\\n\\nThis was caught by the test expectation on the following line:\\n  file:///home/kajo/AndroidStudioProjects/bloc_login/test/integration_test/main_test.dart line 19\\nThe test description was:\\n  Can Login\\n═════════════════════════════════════════════════════════════════\\n\"}"]}}, type: _extensionType, method: ext.flutter.driver}
2022-03-19 13:37:55.908647 >>> {command: get_health}
2022-03-19 13:37:56.196085 <<< {isError: false, response: {status: ok}, type: _extensionType, method: ext.flutter.driver}
2022-03-19 13:37:56.228796 >>> {command: request_data, timeout: 1200000}
2022-03-19 13:37:57.206586 <<< {isError: false, response: {message: {"result":"false","failureDetails":["{\"methodName\":\"Can Login \",\"details\":\"══╡ EXCEPTION CAUGHT BY FLUTTER TEST FRAMEWORK ╞═════════════════\\nThe following TestFailure was thrown running a test:\\nExpected: exactly one matching node in the widget tree\\n  Actual: _WidgetPredicateFinder:<zero widgets with widget\\nmatching predicate (Closure: (Widget) => bool)>\\n   Which: means none were found but one was expected\\n\\nWhen the exception was thrown, this was the stack:\\n#4      main.<anonymous closure> (file:///home/kajo/AndroidStudioProjects/bloc_login/test/integration_test/main_test.dart:19:5)\\n<asynchronous suspension>\\n#5      testWidgets.<anonymous closure>.<anonymous closure> (package:flutter_test/src/widget_tester.dart:170:15)\\n<asynchronous suspension>\\n#6      TestWidgetsFlutterBinding._runTestBody (package:flutter_test/src/binding.dart:833:5)\\n<asynchronous suspension>\\n\\nThis was caught by the test expectation on the following line:\\n  file:///home/kajo/AndroidStudioProjects/bloc_login/test/integration_test/main_test.dart line 19\\nThe test description was:\\n  Can Login\\n═════════════════════════════════════════════════════════════════\\n\"}"]}}, type: _extensionType, method: ext.flutter.driver}
2022-03-19 13:39:02.327112 >>> {command: get_health}
2022-03-19 13:39:02.507364 <<< {isError: false, response: {status: ok}, type: _extensionType, method: ext.flutter.driver}
2022-03-19 13:39:02.542772 >>> {command: request_data, timeout: 1200000}
2022-03-19 13:39:03.564428 <<< {isError: false, response: {message: {"result":"false","failureDetails":["{\"methodName\":\"Can Login \",\"details\":\"══╡ EXCEPTION CAUGHT BY FLUTTER TEST FRAMEWORK ╞═════════════════\\nThe following TestFailure was thrown running a test:\\nExpected: exactly one matching node in the widget tree\\n  Actual: _WidgetPredicateFinder:<zero widgets with widget\\nmatching predicate (Closure: (Widget) => bool)>\\n   Which: means none were found but one was expected\\n\\nWhen the exception was thrown, this was the stack:\\n#4      main.<anonymous closure> (file:///home/kajo/AndroidStudioProjects/bloc_login/test/integration_test/main_test.dart:19:5)\\n<asynchronous suspension>\\n#5      testWidgets.<anonymous closure>.<anonymous closure> (package:flutter_test/src/widget_tester.dart:170:15)\\n<asynchronous suspension>\\n#6      TestWidgetsFlutterBinding._runTestBody (package:flutter_test/src/binding.dart:833:5)\\n<asynchronous suspension>\\n\\nThis was caught by the test expectation on the following line:\\n  file:///home/kajo/AndroidStudioProjects/bloc_login/test/integration_test/main_test.dart line 19\\nThe test description was:\\n  Can Login\\n═════════════════════════════════════════════════════════════════\\n\"}"]}}, type: _extensionType, method: ext.flutter.driver}
2022-03-19 13:48:10.824473 >>> {command: get_health}
2022-03-19 13:48:11.122294 <<< {isError: false, response: {status: ok}, type: _extensionType, method: ext.flutter.driver}
2022-03-19 13:48:11.151792 >>> {command: request_data, timeout: 1200000}
2022-03-19 13:48:12.126051 <<< {isError: false, response: {message: {"result":"false","failureDetails":["{\"methodName\":\"Can Login \",\"details\":\"══╡ EXCEPTION CAUGHT BY FLUTTER TEST FRAMEWORK ╞═════════════════\\nThe following TestFailure was thrown running a test:\\nExpected: exactly one matching node in the widget tree\\n  Actual: _WidgetPredicateFinder:<zero widgets with widget\\nmatching predicate (Closure: (Widget) => bool)>\\n   Which: means none were found but one was expected\\n\\nWhen the exception was thrown, this was the stack:\\n#4      main.<anonymous closure> (file:///home/kajo/AndroidStudioProjects/bloc_login/test/integration_test/main_test.dart:19:5)\\n<asynchronous suspension>\\n#5      testWidgets.<anonymous closure>.<anonymous closure> (package:flutter_test/src/widget_tester.dart:170:15)\\n<asynchronous suspension>\\n#6      TestWidgetsFlutterBinding._runTestBody (package:flutter_test/src/binding.dart:833:5)\\n<asynchronous suspension>\\n\\nThis was caught by the test expectation on the following line:\\n  file:///home/kajo/AndroidStudioProjects/bloc_login/test/integration_test/main_test.dart line 19\\nThe test description was:\\n  Can Login\\n═════════════════════════════════════════════════════════════════\\n\"}"]}}, type: _extensionType, method: ext.flutter.driver}
2022-03-19 17:28:43.120471 >>> {command: request_data, timeout: 1200000}
2022-03-19 17:28:45.171439 <<< {isError: false, response: {message: {"result":"false","failureDetails":["{\"methodName\":\"Can Login \",\"details\":\"══╡ EXCEPTION CAUGHT BY FLUTTER TEST FRAMEWORK ╞═════════════════\\nThe following TestFailure was thrown running a test:\\nExpected: exactly one matching node in the widget tree\\n  Actual: _WidgetPredicateFinder:<zero widgets with widget\\nmatching predicate (Closure: (Widget) => bool from: widget =>\\napp_bar.AppBar.is(widget) && text.Text.is(widget.title) &&\\ntext.Text.as(widget.title).data === \\\"Loginddgg\\\")>\\n   Which: means none were found but one was expected\\n\\nWhen the exception was thrown, this was the stack:\\ndart-sdk/lib/_internal/js_dev_runtime/private/ddc_runtime/errors.dart 251:49  throw_\\npackages/test_api/src/expect/async_matcher.dart.js 145:22                     fail\\npackages/test_api/src/expect/async_matcher.dart.js 142:12                     _expect\\npackages/test_api/src/expect/async_matcher.dart.js 75:12                      expect$\\npackages/flutter_test/src/matchers.dart.js 4559:12                            expect$\\nmain_test.dart.js 49:21                                                       <fn>\\ndart-sdk/lib/_internal/js_dev_runtime/patch/async_patch.dart 45:50            <fn>\\ndart-sdk/lib/async/zone.dart 1434:47                                          _rootRunUnary\\ndart-sdk/lib/async/zone.dart 1335:19                                          runUnary\\ndart-sdk/lib/async/future_impl.dart 147:18                                    handleValue\\ndart-sdk/lib/async/future_impl.dart 766:44                                    handleValueCallback\\ndart-sdk/lib/async/future_impl.dart 795:13                                    _propagateToListeners\\ndart-sdk/lib/async/future_impl.dart 566:5                                     [_completeWithValue]\\ndart-sdk/lib/async/future_impl.dart 639:7                                     <fn>\\ndart-sdk/lib/async/zone.dart 1426:13                                          _rootRun\\ndart-sdk/lib/async/zone.dart 1328:19                                          run\\ndart-sdk/lib/async/zone.dart 1236:7                                           runGuarded\\ndart-sdk/lib/async/zone.dart 1276:23                                          callback\\ndart-sdk/lib/async/schedule_microtask.dart 40:11                              _microtaskLoop\\ndart-sdk/lib/async/schedule_microtask.dart 49:5                               _startMicrotaskLoop\\ndart-sdk/lib/_internal/js_dev_runtime/patch/async_patch.dart 166:15           <fn>\\n\\nThe test description was:\\n  Can Login\\n═════════════════════════════════════════════════════════════════\\n\"}"]}}}
